<?xml version="1.0"?>

<robot name="complete_M.A.R.S_prototype2" xmlns:xacro="http://www.ros.org/wiki/xacro">
<!--WHEELS-->
<xacro:property name="radius" value="0.05"/>
<xacro:property name="length" value="0.026"/>

<!--motors-->
<xacro:property name="radius_of_motor" value="0.026"/>
<xacro:property name="length_of_motor" value="0.10"/>



<!--<xacro:include filename="$(find urdf_package)/urdf/materials.xacro" / -->


<!-- ////////////////////////////////////////////////////////////////////////////////////////////////////////////////////////////////////////////////////////////////////////-->
<!--MATERIAL COLORS -->
  <material name="blue">
    <color rgba="0 0 1 1"/>
  </material>

<material name="red">
    <color rgba="1 0 0 1"/>
  </material>


<material name="pink">
    <color rgba="0.8 0 1 0.5"/>
  </material>


    <material name="white">
    <color rgba="1 1 1 1"/>
  </material>

  <material name="green">
    <color rgba="0 1 0 1"/>
</material>

<gazebo reference="base_link_to_wheel1">
  <material>Gazebo/orange</material>
</gazebo>

<!--///////////////////////////////////////////////////////////////////////////////////////////////////////////////////////////////////////////////////////////////////////////-->

<!--/////////////////////////////////////////////////////////////////////////////////////////////////////////////////////////////////////////////////////////////////////////-->

<!--Visual of the Link-->
  <link name="base_link">         <!--chassis link-->
    <visual>
    
    <geometry>
  
        <box size="0.5 0.40 0.40"/>
       </geometry>
  <!-- Setting up the origin of the link -->
      <origin rpy="0 0 0" xyz="0 0 0"/>
       <material name="blue"/>
    </visual>
<!--  COLLISION -->
    <collision>
      <geometry>
       <box size="0.51 0.41 0.41"/>
       
      </geometry>
      <origin rpy="0 0 0" xyz="0 0 0"/>
    </collision>
<!--  INERTIAL -->
    <inertial>
      <mass value="5.0"/>
      
      <inertia
          ixx="0.1333333" ixy="0.0" ixz="0.0"
          iyy="0.1708333" iyz="0.0"
          izz="0.1708333"
      />
      <origin rpy="0 0 0" xyz="0 0 0"/>
    </inertial>
  
  </link>
 
 <!--/////////////////////////////////////////////////////////////////////////////////////////////////////////////////////////////////////////////////////////////////////////-->
<!--HOLDER1 LEFT FRONT-->
 <link name="holder1">
 <visual>
 <origin rpy="1.57075 0 0" xyz="0.10 0 -0.0025"/>
 <geometry>
 <box size="0.2 0.04 0.005 "/>
 </geometry>
 <material name="Blue"/>
 </visual>
 <collision> 
 <origin rpy="1.57075 0 0" xyz="0.10 0 -0.0025"/>
 <geometry>
 <box size="0.2 0.04 0.005 "/>
 </geometry> 
 </collision>
        
<!-- Inertia of the HOLDER1 -->
<inertial>
      <mass value="0.09"/>
      
      <inertia
          ixx="0.7392092415" ixy="0.0" ixz="0.0"
          iyy="0.0003001875" iyz="0.0"
          izz="0.0003"
      />
      <origin rpy="1.57075 0 0" xyz="0.10 0 -0.0025"/>
    </inertial>
</link>

<joint name="holder1_to_base_link" type="revolute">
      <parent link="base_link"/>
      <child link="holder1"/>
      <origin xyz="0.25 0.20 -0.20" rpy="0 0 0"/>
      <axis xyz="0 1 0" />
      <limit effort="300" velocity="0.1" lower="0.52358" upper="0.261799" />
  </joint>
<!--/////////////////////////////////////////////////////////////////////////////////////////////////////////////////////////////////////////////////////////////////////////-->
<!--PLANETARY MOTOR1-->
 <link name="motor1">
 <visual>
 <origin rpy="1.57075 0 0" xyz="0.10 0 0.0025"/>
 <geometry>
<cylinder radius="${radius_of_motor}" length="${length_of_motor}"/>
 </geometry>
 <material name="green"/>
 </visual>
 <collision> 
 <origin rpy="1.57075 0 0" xyz="0.10 0 -0.0025"/>
 <geometry>
<cylinder radius="${radius_of_motor}" length="${length_of_motor}"/>
 </geometry> 
 </collision>

<!-- Inertia of the motor1 -->
<inertial>
      <mass value="0.09"/>
      
      <inertia
          ixx="0.260166666667" ixy="0.0" ixz="0.0"
          iyy="0.260166666667" iyz="0.0"
          izz="0.4"
      />
      <origin rpy="1.57075 0 0" xyz="0.10 0 0.0025"/>
    </inertial>
</link>
<joint name="holder1_to_motor1" type="fixed">
      <parent link="holder1"/>
      <child link="motor1"/>
      <origin xyz="0.10 -0.05 0" rpy="0 0 0"/>
  </joint>
<!--/////////////////////////////////////////////////////////////////////////////////////////////////////////////////////////////////////////////////////////////////////////-->

<!--WHEEL_1--> 
<!--Visual of the Link-->
  <link name="wheel1">
    <visual>
      <geometry>
      <cylinder radius="${radius}" length="${length}"/>
      </geometry>
  <!-- Setting up the origin of the link -->
       <origin rpy="0 1.57075 1.57075" xyz="0 0.018 0"/>
        <material name="white"/>
    </visual>
     <collision>
<!--  COLLISION -->
     <origin rpy="0 1.57075 1.57075" xyz="0 0 0"/>
      <geometry>
         <cylinder radius="${radius}" length="${length}"/>
      </geometry>
    </collision>
<!--  INERTIAL -->
 <inertial>
      <origin xyz="0 0 0" rpy="0 1.5707 1.5707"/>
      <mass value="0.216"/>
      <cylinder_inertia m="0.216" r="0.05" h="0.026"/>
      <inertia
        ixx="0.000147168" ixy="0.0" ixz="0.0"
        iyy="0.000147168" iyz="0.0"
        izz="0.00027"/>
    </inertial>

  </link>

<joint name="holder1_to_wheel1" type="continuous">
  <axis xyz="0 1 0"/> 
<origin rpy="0 0 0" xyz="0.20 0 0"/>
 <!-- <limit effort="100" velocity="100"/> -->
 <joint_properties damping="0.0" friction="0.0"/>
    <parent link="holder1"/> 
    <child link="wheel1"/>
        
   
  </joint>


<!--/////////////////////////////////////////////////////////////////////////////////////////////////////////////////////////////////////////////////////////////////////////-->
<!--HOLDER2 LEFT REAR-->
 <link name="holder2">
 <visual>
 <origin rpy="1.57075 0 0" xyz="-0.10 0 -0.0025"/>
 <geometry>
 <box size="0.2 0.04 0.005 "/>
 </geometry>
 <material name="Blue"/>
 </visual>
 <collision> 
 <origin rpy="1.57075 0 0" xyz="-0.10 0 -0.0025"/>
 <geometry>
 <box size="0.2 0.04 0.005 "/>
 </geometry> 
 </collision>
        
<!-- Inertia of the HOLDER 2 -->
<inertial>
      <mass value="0.09"/>
      
      <inertia
          ixx="0.7392092415" ixy="0.0" ixz="0.0"
          iyy="0.0003001875" iyz="0.0"
          izz="0.0003"
      />
      <origin rpy="1.57075 0 0" xyz="-0.10 0 -0.0025"/>
    </inertial>
</link>

<joint name="holder2_to_base_link" type="revolute">
      <parent link="base_link"/>
      <child link="holder2"/>
      <origin xyz="-0.25 0.20 -0.20" rpy="0 0 0"/>
      <axis xyz="0 1 0" />
      <limit effort="300" velocity="0.1" lower="-0.52358" upper="-0.261799" />
  </joint>

<!--/////////////////////////////////////////////////////////////////////////////////////////////////////////////////////////////////////////////////////////////////////////-->
<!--PLANETARY MOTOR2-->
 <link name="motor2">
 <visual>
 <origin rpy="1.57075 0 0" xyz="-0.10 0 0.0025"/>
 <geometry>
<cylinder radius="${radius_of_motor}" length="${length_of_motor}"/>
 </geometry>
 <material name="green"/>
 </visual>
 <collision> 
 <origin rpy="1.57075 0 0" xyz="-0.10 0 -0.0025"/>
 <geometry>
<cylinder radius="${radius_of_motor}" length="${length_of_motor}"/>
 </geometry> 
 </collision>

<!-- Inertia of the motor2 -->
<inertial>
      <mass value="0.09"/>
      
      <inertia
          ixx="0.260166666667" ixy="0.0" ixz="0.0"
          iyy="0.260166666667" iyz="0.0"
          izz="0.4"
      />
      <origin rpy="1.57075 0 0" xyz="-0.10 0 0.0025"/>
    </inertial>
</link>
<joint name="holder2_to_motor2" type="fixed">
      <parent link="holder2"/>
      <child link="motor2"/>
      <origin xyz="-0.10 -0.05 0" rpy="0 0 0"/>
  </joint>
<!--/////////////////////////////////////////////////////////////////////////////////////////////////////////////////////////////////////////////////////////////////////////-->

<!--WHEEL_2--> 
<!--Visual of the Link-->
  <link name="wheel2">
    <visual>
      <geometry>
      <cylinder radius="${radius}" length="${length}"/>
      </geometry>
  <!-- Setting up the origin of the link -->
       <origin rpy="0 1.57075 1.57075" xyz="0 0.018 0"/>
        <material name="white"/>
    </visual>
     <collision>
<!--  COLLISION -->
     <origin rpy="0 1.57075 1.57075" xyz="0 0 0"/>
      <geometry>
         <cylinder radius="${radius}" length="${length}"/>
      </geometry>
    </collision>
<!--  INERTIAL -->
 <inertial>
      <origin xyz="0 0 0" rpy="0 1.5707 1.5707"/>
      <mass value="0.216"/>
      <cylinder_inertia m="0.216" r="0.05" h="0.026"/>
      <inertia
        ixx="0.000147168" ixy="0.0" ixz="0.0"
        iyy="0.000147168" iyz="0.0"
        izz="0.00027"/>
    </inertial>

  </link>

<joint name="holder2_to_wheel2" type="continuous">
  <axis xyz="0 1 0"/> 
<origin rpy="0 0 0" xyz="-0.20 0 0"/>
 <!-- <limit effort="100" velocity="100"/> -->
 <joint_properties damping="0.0" friction="0.0"/>
    <parent link="holder2"/> 
    <child link="wheel2"/>
        
   
  </joint>
<!--/////////////////////////////////////////////////////////////////////////////////////////////////////////////////////////////////////////////////////////////////////////-->
<!--HOLDER3 LEFT FRONT-->
 <link name="holder3">
 <visual>
 <origin rpy="1.57075 0 0" xyz="0.10 0 -0.0025"/>
 <geometry>
 <box size="0.2 0.04 0.005 "/>
 </geometry>
 <material name="Blue"/>
 </visual>
 <collision> 
 <origin rpy="1.57075 0 0" xyz="0.10 0 -0.0025"/>
 <geometry>
 <box size="0.2 0.04 0.005 "/>
 </geometry> 
 </collision>
        
<!-- Inertia of the HOLDER3 -->
<inertial>
      <mass value="0.09"/>
      
      <inertia
          ixx="0.7392092415" ixy="0.0" ixz="0.0"
          iyy="0.0003001875" iyz="0.0"
          izz="0.0003"
      />
      <origin rpy="1.57075 0 0" xyz="0.10 0 -0.0025"/>
    </inertial>
</link>

<joint name="holder3_to_base_link" type="revolute">
      <parent link="base_link"/>
      <child link="holder3"/>
      <origin xyz="0.25 -0.20 -0.20" rpy="0 0 0"/>
      <axis xyz="0 1 0" />
      <limit effort="300" velocity="0.1" lower="0.52358" upper="0.261799" />
  </joint>
<!--/////////////////////////////////////////////////////////////////////////////////////////////////////////////////////////////////////////////////////////////////////////-->
<!--PLANETARY MOTOR3-->
 <link name="motor3">
 <visual>
 <origin rpy="1.57075 0 0" xyz="0.10 0 0.0025"/>
 <geometry>
<cylinder radius="${radius_of_motor}" length="${length_of_motor}"/>
 </geometry>
 <material name="green"/>
 </visual>
 <collision> 
 <origin rpy="1.57075 0 0" xyz="0.10 0 -0.0025"/>
 <geometry>
<cylinder radius="${radius_of_motor}" length="${length_of_motor}"/>
 </geometry> 
 </collision>

<!-- Inertia of the motor3 -->
<inertial>
      <mass value="0.09"/>
      
      <inertia
          ixx="0.260166666667" ixy="0.0" ixz="0.0"
          iyy="0.260166666667" iyz="0.0"
          izz="0.4"
      />
      <origin rpy="1.57075 0 0" xyz="0.10 0 0.0025"/>
    </inertial>
</link>
<joint name="holder3_to_motor3" type="fixed">
      <parent link="holder3"/>
      <child link="motor3"/>
      <origin xyz="0.10 0.05 0" rpy="0 0 0"/>
  </joint>
<!--/////////////////////////////////////////////////////////////////////////////////////////////////////////////////////////////////////////////////////////////////////////-->

<!--WHEEL_3--> 
<!--Visual of the Link-->
  <link name="wheel3">
    <visual>
      <geometry>
      <cylinder radius="${radius}" length="${length}"/>
      </geometry>
  <!-- Setting up the origin of the link -->
       <origin rpy="0 1.57075 1.57075" xyz="0 -0.018 0"/>
        <material name="white"/>
    </visual>
     <collision>
<!--  COLLISION -->
     <origin rpy="0 1.57075 1.57075" xyz="0 0 0"/>
      <geometry>
         <cylinder radius="${radius}" length="${length}"/>
      </geometry>
    </collision>
<!--  INERTIAL -->
 <inertial>
      <origin xyz="0 0 0" rpy="0 1.5707 1.5707"/>
      <mass value="0.216"/>
      <cylinder_inertia m="0.216" r="0.05" h="0.026"/>
      <inertia
        ixx="0.000147168" ixy="0.0" ixz="0.0"
        iyy="0.000147168" iyz="0.0"
        izz="0.00027"/>
    </inertial>

  </link>

<joint name="holder3_to_wheel3" type="continuous">
  <axis xyz="0 1 0"/> 
<origin rpy="0 0 0" xyz="0.20 0 0"/>
 <!-- <limit effort="100" velocity="100"/> -->
 <joint_properties damping="0.0" friction="0.0"/>
    <parent link="holder3"/> 
    <child link="wheel3"/>
        
   
  </joint>

<!--/////////////////////////////////////////////////////////////////////////////////////////////////////////////////////////////////////////////////////////////////////////-->
 <!--/////////////////////////////////////////////////////////////////////////////////////////////////////////////////////////////////////////////////////////////////////////-->
<!--HOLDER4 LEFT FRONT-->
 <link name="holder4">
 <visual>
 <origin rpy="1.57075 0 0" xyz="-0.10 0 -0.0025"/>
 <geometry>
 <box size="0.2 0.04 0.005 "/>
 </geometry>
 <material name="Blue"/>
 </visual>
 <collision> 
 <origin rpy="1.57075 0 0" xyz="-0.10 0 -0.0025"/>
 <geometry>
 <box size="0.2 0.04 0.005 "/>
 </geometry> 
 </collision>
        
<!-- Inertia of the HOLDER4 -->
<inertial>
      <mass value="0.09"/>
      
      <inertia
          ixx="0.7392092415" ixy="0.0" ixz="0.0"
          iyy="0.0003001875" iyz="0.0"
          izz="0.0003"
      />
      <origin rpy="1.57075 0 0" xyz="-0.10 0 -0.0025"/>
    </inertial>
</link>

<joint name="holder4_to_base_link" type="revolute">
      <parent link="base_link"/>
      <child link="holder4"/>
      <origin xyz="-0.25 -0.20 -0.20" rpy="0 0 0"/>
      <axis xyz="0 1 0" />
      <limit effort="300" velocity="0.1" lower="-0.52358" upper="-0.261799" />
  </joint>
<!--/////////////////////////////////////////////////////////////////////////////////////////////////////////////////////////////////////////////////////////////////////////-->
<!--PLANETARY MOTOR4-->
 <link name="motor4">
 <visual>
 <origin rpy="1.57075 0 0" xyz="-0.10 0 0.0025"/>
 <geometry>
<cylinder radius="${radius_of_motor}" length="${length_of_motor}"/>
 </geometry>
 <material name="green"/>
 </visual>
 <collision> 
 <origin rpy="1.57075 0 0" xyz="0.10 0 -0.0025"/>
 <geometry>
<cylinder radius="${radius_of_motor}" length="${length_of_motor}"/>
 </geometry> 
 </collision>

<!-- Inertia of the motor4 -->
<inertial>
      <mass value="0.09"/>
      
      <inertia
          ixx="0.260166666667" ixy="0.0" ixz="0.0"
          iyy="0.260166666667" iyz="0.0"
          izz="0.4"
      />
      <origin rpy="1.57075 0 0" xyz="-0.10 0 0.0025"/>
    </inertial>
</link>
<joint name="holder4_to_motor4" type="fixed">
      <parent link="holder4"/>
      <child link="motor4"/>
      <origin xyz="-0.10 0.05 0" rpy="0 0 0"/>
  </joint>
<!--/////////////////////////////////////////////////////////////////////////////////////////////////////////////////////////////////////////////////////////////////////////-->

<!--WHEEL_4--> 
<!--Visual of the Link-->
  <link name="wheel4">
    <visual>
      <geometry>
      <cylinder radius="${radius}" length="${length}"/>
      </geometry>
  <!-- Setting up the origin of the link -->
       <origin rpy="0 1.57075 1.57075" xyz="0 -0.018 0"/>
        <material name="white"/>
    </visual>
     <collision>
<!--  COLLISION -->
     <origin rpy="0 1.57075 1.57075" xyz="0 0 0"/>
      <geometry>
         <cylinder radius="${radius}" length="${length}"/>
      </geometry>
    </collision>
<!--  INERTIAL -->
 <inertial>
      <origin xyz="0 0 0" rpy="0 1.5707 1.5707"/>
      <mass value="0.216"/>
      <cylinder_inertia m="0.216" r="0.05" h="0.026"/>
      <inertia
        ixx="0.000147168" ixy="0.0" ixz="0.0"
        iyy="0.000147168" iyz="0.0"
        izz="0.00027"/>
    </inertial>

  </link>

<joint name="holder4_to_wheel4" type="continuous">
  <axis xyz="0 1 0"/> 
<origin rpy="0 0 0" xyz="-0.20 0 0"/>
 <!-- <limit effort="100" velocity="100"/> -->
 <joint_properties damping="0.0" friction="0.0"/>
    <parent link="holder4"/> 
    <child link="wheel4"/>
        
   
  </joint>

<!--/////////////////////////////////////////////////////////////////////////////////////////////////////////////////////////////////////////////////////////////////////////-->


  <link name="kinect">


    <visual>
      <geometry>
        <mesh filename="package://urdf_package/meshes/kinect.dae"/>
       </geometry>
      <origin rpy="0 0 0" xyz="0 0 0"/>
      
    </visual>
    </link>

     <joint name="base_link_to_kinect" type="fixed">
  <axis xyz="0 0 0"/> 
<origin rpy="0 0 1.5707" xyz="0.135 0 0.08"/>
 
    <parent link="base_link"/> 
    <child link="kinect"/>
        
   
  </joint>

  <link name="imu">
  <visual>
      <geometry>       
        <box size="0.05 0.04 0.02"/>
       </geometry>
      <origin rpy="0 0 0" xyz="0 0 0"/>
    </visual>
    </link>
<joint name="base_link_to_imu" type="fixed">
  <axis xyz="0 0 0"/> 
<origin rpy="0 0 1.5707" xyz="0 0 0"/>
 
    <parent link="base_link"/> 
    <child link="imu"/>
        
   
  </joint>


<!--

<gazebo>
  <plugin name="skid_steer_drive_controller" filename="libgazebo_ros_skid_steer_drive.so">
    <updateRate>100.0</updateRate>
    <robotNamespace>/complete_M.A.R.S_prototype2</robotNamespace>
    <leftFrontJoint>base_link_to_wheel1</leftFrontJoint>
    <rightFrontJoint>base_link_to_wheel2</rightFrontJoint>cd
    <leftRearJoint>base_link_to_wheel3</leftRearJoint>
    <rightRearJoint>base_link_to_wheel4</rightRearJoint>
    <wheelSeparation>0.46</wheelSeparation>
    <wheelDiameter>0.15</wheelDiameter>
    <robotBaseFrame>base_link</robotBaseFrame>
    <torque>20</torque> 
    <topicName>cmd_vel</topicName>
    <broadcastTF>false</broadcastTF>
    
  </plugin>
</gazebo>
-->


<!-- /////////////////////////////////////////////////////////////////////-->
<!-- GAZEBO PHYSICAL PROPERTIES-->
 <gazebo reference="base_link_to_wheel1">
      <mu1 value="200.0"/>
      <mu2 value="100.0"/>
      <kp value="10000000.0" />
      <kd value="1.0" />
      <material>Gazebo/Grey</material>
    </gazebo>
<gazebo reference="base_link_to_wheel2">
      <mu1 value="200.0"/>
      <mu2 value="100.0"/>
      <kp value="10000000.0" />
      <kd value="1.0" />
      <material>Gazebo/Grey</material>
    </gazebo>
    <gazebo reference="base_link_to_wheel3">
      <mu1 value="200.0"/>
      <mu2 value="100.0"/>
      <kp value="10000000.0" />
      <kd value="1.0" />
      <material>Gazebo/Grey</material>
    </gazebo>
    <gazebo reference="base_link_to_wheel4">
      <mu1 value="200.0"/>
      <mu2 value="100.0"/>
      <kp value="10000000.0" />
      <kd value="1.0" />
      <material>Gazebo/Grey</material>
    </gazebo>


 <!-- /////////////////////////////////////////////////////////////////////-->
<!-- wheel 1 transmission tag-->


<transmission name="base_to_wheel1">
  <type>transmission_interface/SimpleTransmission</type>
  <actuator name="motor1">
  <mechanicalReduction>1</mechanicalReduction>
     <hardwareInterface>EffortJointInterface</hardwareInterface>

</actuator>
<joint name="base_link_to_wheel1">
   <hardwareInterface>hardware_interface/VelocityJointInterface</hardwareInterface>
</joint>
</transmission>


    <!-- /////////////////////////////////////////////////////////////////////-->
<!-- wheel 2 transmission tag-->

<transmission name="base_to_wheel2">
  <type>transmission_interface/SimpleTransmission</type>
  <actuator name="motor2">
  <mechanicalReduction>1</mechanicalReduction>
 <hardwareInterface>EffortJointInterface</hardwareInterface>

</actuator>
<joint name="base_link_to_wheel2">
   <hardwareInterface>hardware_interface/VelocityJointInterface</hardwareInterface>
</joint>
</transmission>

<!-- /////////////////////////////////////////////////////////////////////-->
<!-- wheel 3 transmission tag-->

<transmission name="base_to_wheel3">
  <type>transmission_interface/SimpleTransmission</type>
  <actuator name="motor3">
  <mechanicalReduction>1</mechanicalReduction>
   <hardwareInterface>EffortJointInterface</hardwareInterface>

</actuator>
<joint name="base_link_to_wheel3">
   <hardwareInterface>hardware_interface/VelocityJointInterface</hardwareInterface>
</joint>
</transmission>

<!-- /////////////////////////////////////////////////////////////////////-->
<!-- wheel 4 transmission tag-->

<transmission name="base_to_wheel4">
  <type>transmission_interface/SimpleTransmission</type>
  <actuator name="motor4">
  <mechanicalReduction>1</mechanicalReduction>
   <hardwareInterface>EffortJointInterface</hardwareInterface>

</actuator>
<joint name="base_link_to_wheel4">
   <hardwareInterface>hardware_interface/VelocityJointInterface</hardwareInterface>
</joint>
</transmission>
<!-- /////////////////////////////////////////////////////////////////////-->


<gazebo>
<plugin name="gazbo_ros_control" filename="libgazebo_ros_control.so">
<robotNamespace>/</robotNamespace>
</plugin>

</gazebo>

 <!-- camera -->
  <gazebo reference="camera_link">
    <sensor type="depth" name="camera1">
        <always_on>1</always_on>
        <visualize>true</visualize>             
        <camera>
            <horizontal_fov>1.047</horizontal_fov>  
            <image>
                <width>640</width>
                <height>480</height>
                <format>R8G8B8</format>
            </image>
            <depth_camera>

            </depth_camera>
            <clip>
                <near>0.1</near>
                <far>100</far>
            </clip>
        </camera>
             <plugin name="camera_controller" filename="libgazebo_ros_openni_kinect.so">
             <alwaysOn>true</alwaysOn>
                <updateRate>10.0</updateRate>
                <cameraName>camera</cameraName>
                <frameName>camera_link</frameName>                   
            <imageTopicName>rgb/image_raw</imageTopicName>
            <depthImageTopicName>depth/image_raw</depthImageTopicName>
            <pointCloudTopicName>depth/points</pointCloudTopicName>
            <cameraInfoTopicName>rgb/camera_info</cameraInfoTopicName>              
            <depthImageCameraInfoTopicName>depth/camera_info</depthImageCameraInfoTopicName>            
            <pointCloudCutoff>0.4</pointCloudCutoff>                
                <hackBaseline>0.07</hackBaseline>
                <distortionK1>0.0</distortionK1>
                <distortionK2>0.0</distortionK2>
                <distortionK3>0.0</distortionK3>
                <distortionT1>0.0</distortionT1>
                <distortionT2>0.0</distortionT2>
            <CxPrime>0.0</CxPrime>
            <Cx>0.0</Cx>
            <Cy>0.0</Cy>
            <focalLength>0.0</focalLength>
            </plugin>
    </sensor>
  </gazebo>



</robot>

