<?xml version="1.0"?>

<robot name="complete_M.A.R.S_prototype2" xmlns:xacro="http://www.ros.org/wiki/xacro">
<!-- <xacro:property name="radius" value="0.075" />
<xacro:property name="length" value="0.06" />
-->

<!--<xacro:include filename="$(find urdf_package)/urdf/materials.xacro" / -->


<!-- ////////////////////////////////////////////////////////////////////////////////////////////////////////////////////////////////////////////////////////////////////////-->
<!--MATERIAL COLORS -->
  <material name="blue">
    <color rgba="0 0 1 1"/>
  </material>

<material name="red">
    <color rgba="1 0 0 1"/>
  </material>


<material name="pink">
    <color rgba="0.8 0 1 0.5"/>
  </material>


    <material name="white">
    <color rgba="1 1 1 1"/>
  </material>

  <material name="green">
    <color rgba="0 1 0 1"/>
</material>

<gazebo reference="base_link_to_wheel1">
  <material>Gazebo/orange</material>
</gazebo>

<!--///////////////////////////////////////////////////////////////////////////////////////////////////////////////////////////////////////////////////////////////////////////-->

<!--
<! Macros for inertia matrix calculations-
<property name="M_PI" value="3.1415926535897931" />
 <xacro:macro name="sphere_inertial" params="radius mass">
    <inertial>
      <mass value="${mass}" />
      <origin xyz="0 0 0" />
      <inertia ixx="${0.4 * mass * radius * radius}" ixy="0.0" ixz="0.0"
        iyy="${0.4 * mass * radius * radius}" iyz="0.0"
        izz="${0.4 * mass * radius * radius}" />
    </inertial>
  </xacro:macro>

  <xacro:macro name="cylinder_inertial" params="radius length mass">
    <inertial>
      <mass value="${mass}" />
      <origin xyz="0 0 0" />
      <inertia ixx="${0.0833333 * mass * (3 * radius * radius + length * length)}" ixy="0.0" ixz="0.0"
        iyy="${0.0833333 * mass * (3 * radius * radius + length * length)}" iyz="0.0"
        izz="${0.5 * mass * radius * radius}" />
    </inertial>
  </xacro:macro>

    <xacro:macro name="box_inertial" params="x y z mass">
    <inertial>
      <mass value="${mass}" />
      <origin xyz="0 0 0" />
      <inertia ixx="${ 0.0833333 * mass * ( y * y + z * z )}" ixy="0.0" ixz="0.0"
        iyy="${0.0833333 * mass * ( x * x + z * z )}" iyz="0.0"
        izz="${0.0833333 * mass * (x * x + y * y)}" />
    </inertial>
</xacro:macro>
)-->
<!--/////////////////////////////////////////////////////////////////////////////////////////////////////////////////////////////////////////////////////////////////////////-->
<link name="dummy_link">
      <origin rpy="0 0 0" xyz="0 0 0"/>
 </link>
<joint name="dummy_link_to_base_link" type="fixed">
  <axis xyz="0 0 0"/> 
<origin rpy="0 0 0" xyz="0 0 0"/>
 <!-- <limit effort="100" velocity="100"/> -->
    <parent link="dummy_link"/> 
    <child link="base_link"/>
        
   
  </joint>







<!--/////////////////////////////////////////////////////////////////////////////////////////////////////////////////////////////////////////////////////////////////////////-->
<!--Visual of the Link-->
  <link name="base_link">
    <visual>
    
    <geometry>
  
        <box size="0.5 0.40 0.40"/>
       </geometry>
  <!-- Setting up the origin of the link -->
      <origin rpy="0 0 0" xyz="0 0 0.275"/>
       <material name="blue"/>
    </visual>
<!--  COLLISION -->
    <collision>
      <geometry>
       <box size="0.51 0.41 0.41"/>
       
      </geometry>
      <origin rpy="0 0 0" xyz="0 0 0.275"/>
    </collision>
<!--  INERTIAL -->
    <inertial>
      <mass value="5.0"/>
      
      <inertia
          ixx="0.1333333" ixy="0" ixz="0"
          iyy="0.1708333" iyz="0"
          izz="0.1708333"
      />
      <origin rpy="0 0 0" xyz="0 0 0.275"/>
    </inertial>
  
  </link>
 
 
<!--/////////////////////////////////////////////////////////////////////////////////////////////////////////////////////////////////////////////////////////////////////////-->
<!--WHEEL_1--> 
<!--Visual of the Link-->
  <link name="wheel1">
    <visual>
      <geometry>
      <cylinder radius="0.075" length="0.06"/>
         
      </geometry>
  <!-- Setting up the origin of the link -->
       <origin rpy="0 1.57075 1.57075" xyz="0 0 0"/>
        <material name="white"/>
    </visual>
     <collision>
<!--  COLLISION -->
     <origin rpy="0 1.57075 1.57075" xyz="0 0 0"/>
      <geometry>
         <cylinder radius="0.075" length="0.06"/>
      </geometry>
    </collision>
<!--  INERTIAL -->
 <inertial>
      <origin xyz="0 0 0" rpy="0 1.5707 1.5707"/>
      <mass value="0.4"/>
      <cylinder_inertia m="0.4" r="0.075" h="0.06"/>
      <inertia
        ixx="0.0006825" ixy="0.0" ixz="0.0"
        iyy="0.0006825" iyz="0.0"
        izz="0.001125"/>
    </inertial>

  </link>

<joint name="base_link_to_wheel1" type="continuous">
  <axis xyz="0 1 0"/> 
<origin rpy="0 0 0" xyz="0.125 0.23 0.075"/>
 <!-- <limit effort="100" velocity="100"/> -->
 <joint_properties damping="1.0" friction="0.0"/>
    <parent link="base_link"/> 
    <child link="wheel1"/>
        
   
  </joint>


<!--/////////////////////////////////////////////////////////////////////////////////////////////////////////////////////////////////////////////////////////////////////////-->
<!--WHEEL_2-->
<!--Visual of the Link-->
<link name="wheel2">
    <visual>
      <geometry>
         <cylinder radius="0.075" length="0.06"/>
      </geometry>
  <!-- Setting up the origin of the link -->
       <origin rpy="0 1.57075 1.57075" xyz="0 0 0"/>
       <material name="white"/>
    </visual>
     <collision>
<!--  COLLISION -->
     <origin rpy="0 1.57075 1.57075" xyz="0 0 0"/>
      <geometry>
         <cylinder radius="0.075" length="0.06"/>
      </geometry>
    </collision>
<!--  INERTIAL -->
    <inertial>
      <origin xyz="0 0 0" rpy="0 1.5707 1.5707"/>
      <mass value="0.4"/>
      <cylinder_inertia m="0.4" r="0.075" h="0.06"/>
      <inertia
        ixx="0.0006825" ixy="0.0" ixz="0.0"
        iyy="0.0006825" iyz="0.0"
        izz="0.001125"/>
    </inertial>
  </link>

<joint name="base_link_to_wheel2" type="continuous">
    <parent link="base_link"/>
    <child link="wheel2"/>
    <origin rpy="0 0 0" xyz="-0.125 0.23 0.075"/>
   <!--  <limit effort="100" velocity="100"/> -->
    <joint_properties damping="1.0" friction="0.0"/>
    <axis xyz="0 1 0"/>
   
  </joint>
<!--/////////////////////////////////////////////////////////////////////////////////////////////////////////////////////////////////////////////////////////////////////////-->
<!--WHEEL_3-->
<!--Visual of the Link-->
<link name="wheel3">
    <visual>
      <geometry>
  <!-- Setting up the origin of the link -->
         <cylinder radius="0.075" length="0.06"/>
      </geometry>
       <origin rpy="0 1.57075 1.57075" xyz="0 0 0"/>
          <material name="white"/>
    </visual>
    <collision>
<!--  COLLISION -->
    <origin rpy="0 1.57075 1.57075" xyz="0 0 0"/>
      <geometry>
        <cylinder radius="0.075" length="0.06"/>
      </geometry>
    </collision>
<!--  INERTIAL -->
    <inertial>
      <origin xyz="0 0 0" rpy="0 1.5707 1.5707"/>
      <mass value="0.4"/>
      <cylinder_inertia m="0.4" r="0.075" h="0.06"/>
      <inertia
        ixx="0.0006825" ixy="0.0" ixz="0.0"
        iyy="0.0006825" iyz="0.0"
        izz="0.001125"/>
    </inertial>
  </link>

    <joint name="base_link_to_wheel3" type="continuous">
    <parent link="base_link"/>
    <child link="wheel3"/>
    <axis xyz="0 1 0"/>
   <!-- <limit effort="100" velocity="100"/>  -->
    <joint_properties damping="1.0" friction="0.0"/>
   <origin  xyz="0.125 -0.23 0.075"/>
     
  </joint>
<!--/////////////////////////////////////////////////////////////////////////////////////////////////////////////////////////////////////////////////////////////////////////-->
<!--WHEEL_4-->
<!--Visual of the Link-->
<link name="wheel4">
    <visual>
      <geometry>
  <!-- Setting up the origin of the link -->
        <cylinder radius="0.075" length="0.06"/>
      </geometry>
       <origin rpy="0 1.57075 1.57075" xyz="0 0 0"/>
      <material name="white"/>
    </visual>
<collision>
<!--  COLLISION -->
<origin rpy="0 1.57075 1.57075" xyz="0 0 0"/>
      <geometry>
         <cylinder radius="0.075" length="0.06"/>
      </geometry>
    </collision>
<!--  INERTIAL -->
    <inertial>
      <origin xyz="0 0 0" rpy="0 1.5707 1.5707"/>
      <mass value="0.4"/>
      <cylinder_inertia m="0.4" r="0.075" h="0.06"/>
      <inertia
        ixx="0.0006825" ixy="0.0" ixz="0.0"
        iyy="0.0006825" iyz="0.0"
        izz="0.001125"/>
    </inertial>
  </link>

    <joint name="base_link_to_wheel4" type="continuous">
    <parent link="base_link"/>
    <child link="wheel4"/>
   <!-- <limit effort="100" velocity="100"/> -->
    <joint_properties damping="1.0" friction="0.0"/>
    <axis xyz="0 1 0"/>
    <origin  xyz="-0.125 -0.23 0.075"/>
    
  </joint>
<!--/////////////////////////////////////////////////////////////////////////////////////////////////////////////////////////////////////////////////////////////////////////-->


  <!--<link name="kinect">


    <visual>
      <geometry>
        <mesh filename="package://urdf_package/meshes/kinect.dae"/>
       </geometry>
      <origin rpy="0 0 0" xyz="0 0 0"/>
      
    </visual>
    </link>

     <joint name="base_link_to_kinect" type="fixed">
  <axis xyz="0 0 0"/> 
<origin rpy="0 0 1.5707" xyz="0.30 0 0.5631"/>
 
    <parent link="base_link"/> 
    <child link="kinect"/>
        
   
  </joint> -->


<!--

<gazebo>
  <plugin name="skid_steer_drive_controller" filename="libgazebo_ros_skid_steer_drive.so">
    <updateRate>100.0</updateRate>
    <robotNamespace>/complete_M.A.R.S_prototype2</robotNamespace>
    <leftFrontJoint>base_link_to_wheel1</leftFrontJoint>
    <rightFrontJoint>base_link_to_wheel2</rightFrontJoint>cd
    <leftRearJoint>base_link_to_wheel3</leftRearJoint>
    <rightRearJoint>base_link_to_wheel4</rightRearJoint>
    <wheelSeparation>0.46</wheelSeparation>
    <wheelDiameter>0.15</wheelDiameter>
    <robotBaseFrame>base_link</robotBaseFrame>
    <torque>20</torque> 
    <topicName>cmd_vel</topicName>
    <broadcastTF>false</broadcastTF>
    
  </plugin>
</gazebo>
-->


<!-- /////////////////////////////////////////////////////////////////////-->
<!-- GAZEBO PHYSICAL PROPERTIES-->
 <gazebo reference="base_link_to_wheel1">
      <mu1 value="200.0"/>
      <mu2 value="100.0"/>
      <kp value="10000000.0" />
      <kd value="1.0" />
      <material>Gazebo/Grey</material>
    </gazebo>
<gazebo reference="base_link_to_wheel2">
      <mu1 value="200.0"/>
      <mu2 value="100.0"/>
      <kp value="10000000.0" />
      <kd value="1.0" />
      <material>Gazebo/Grey</material>
    </gazebo>
    <gazebo reference="base_link_to_wheel3">
      <mu1 value="200.0"/>
      <mu2 value="100.0"/>
      <kp value="10000000.0" />
      <kd value="1.0" />
      <material>Gazebo/Grey</material>
    </gazebo>
    <gazebo reference="base_link_to_wheel4">
      <mu1 value="200.0"/>
      <mu2 value="100.0"/>
      <kp value="10000000.0" />
      <kd value="1.0" />
      <material>Gazebo/Grey</material>
    </gazebo>


 <!-- /////////////////////////////////////////////////////////////////////-->
<!-- wheel 1 transmission tag-->


<transmission name="base_to_wheel1">
  <type>transmission_interface/SimpleTransmission</type>
  <actuator name="motor1">
  <mechanicalReduction>1</mechanicalReduction>
     <hardwareInterface>EffortJointInterface</hardwareInterface>

</actuator>
<joint name="base_link_to_wheel1">
   <hardwareInterface>hardware_interface/VelocityJointInterface</hardwareInterface>
</joint>
</transmission>


    <!-- /////////////////////////////////////////////////////////////////////-->
<!-- wheel 2 transmission tag-->

<transmission name="base_to_wheel2">
  <type>transmission_interface/SimpleTransmission</type>
  <actuator name="motor2">
  <mechanicalReduction>1</mechanicalReduction>
 <hardwareInterface>EffortJointInterface</hardwareInterface>

</actuator>
<joint name="base_link_to_wheel2">
   <hardwareInterface>hardware_interface/VelocityJointInterface</hardwareInterface>
</joint>
</transmission>

<!-- /////////////////////////////////////////////////////////////////////-->
<!-- wheel 3 transmission tag-->

<transmission name="base_to_wheel3">
  <type>transmission_interface/SimpleTransmission</type>
  <actuator name="motor3">
  <mechanicalReduction>1</mechanicalReduction>
   <hardwareInterface>EffortJointInterface</hardwareInterface>

</actuator>
<joint name="base_link_to_wheel3">
   <hardwareInterface>hardware_interface/VelocityJointInterface</hardwareInterface>
</joint>
</transmission>

<!-- /////////////////////////////////////////////////////////////////////-->
<!-- wheel 4 transmission tag-->

<transmission name="base_to_wheel4">
  <type>transmission_interface/SimpleTransmission</type>
  <actuator name="motor4">
  <mechanicalReduction>1</mechanicalReduction>
   <hardwareInterface>EffortJointInterface</hardwareInterface>

</actuator>
<joint name="base_link_to_wheel4">
   <hardwareInterface>hardware_interface/VelocityJointInterface</hardwareInterface>
</joint>
</transmission>
<!-- /////////////////////////////////////////////////////////////////////-->

<gazebo>
  <plugin name="gazbo_ros_control" filename="libgazebo_ros_control.so">
      <robotNamespace>/</robotNamespace>
</plugin>
</gazebo>



</robot>
